#VRML_SIM R2019b utf8
WorldInfo {
}
Viewpoint {
  orientation 0.2062133541812525 -0.9741666558561265 -0.09206182257270748 4.691283579008855
  position 1.3850257218172217 0.5420494855889832 -0.16955099891082015
}
TexturedBackground {
}
TexturedBackgroundLight {
}
Floor {
}
Robot {
  translation 0 0.05 0
  children [
    DEF BODY Group {
      children [
        Shape {
          appearance DEF BODY_COLOR PBRAppearance {
            baseColor 0.533333 0.541176 0.521569
            roughness 1
            metalness 0
          }
          geometry Box {
            size 0.4 0.01 0.2
          }
        }
        Transform {
          translation 0 0.055 0.09
          rotation 1 0 0 1.57
          children [
            Shape {
              appearance USE BODY_COLOR
              geometry DEF BODY_LAYER Box {
                size 0.4 0.02 0.1
              }
            }
          ]
          rotationStep 0.261799
        }
        Transform {
          translation 0 0.055 -0.09
          rotation 1 0 0 1.57
          children [
            Shape {
              appearance USE BODY_COLOR
              geometry USE BODY_LAYER
            }
          ]
        }
      ]
    }
    DEF WHEELS Group {
      children [
        HingeJoint {
          jointParameters HingeJointParameters {
            axis 0 0 1
            anchor 0.1 0 0.105
          }
          endPoint Solid {
            translation 0.1 0 0.105
            rotation 1 0 0 1.57
            children [
              DEF WHEEL_SHAPE Shape {
                appearance DEF WHEEL_COLOR PBRAppearance {
                  baseColor 0 0 0
                  roughness 1
                  metalness 0
                }
                geometry DEF WHEEL_GEO Cylinder {
                  height 0.01
                  radius 0.05
                }
              }
            ]
            boundingObject USE WHEEL_GEO
            physics Physics {
            }
          }
        }
        HingeJoint {
          jointParameters HingeJointParameters {
            axis 0 0 1
            anchor 0.1 0 -0.105
          }
          endPoint Solid {
            translation 0.1 0 -0.105
            rotation 1 0 0 1.57
            children [
              USE WHEEL_SHAPE
            ]
            name "solid(1)"
            boundingObject USE WHEEL_SHAPE
            physics Physics {
            }
          }
        }
        HingeJoint {
          jointParameters HingeJointParameters {
            axis 0 0 1
            anchor -0.1 0 0.105
          }
          endPoint Solid {
            translation -0.1 0 0.105
            rotation 1 0 0 1.57
            children [
              USE WHEEL_SHAPE
            ]
            name "solid(2)"
            boundingObject USE WHEEL_SHAPE
            physics Physics {
            }
          }
        }
        HingeJoint {
          jointParameters HingeJointParameters {
            axis 0 0 1
            anchor -0.1 0 -0.105
          }
          endPoint Solid {
            translation -0.1 0 -0.105
            rotation 1 0 0 1.57
            children [
              USE WHEEL_SHAPE
            ]
            name "solid(3)"
            boundingObject USE WHEEL_SHAPE
            physics Physics {
            }
          }
        }
      ]
    }
    DEF ROBOT_ARM Group {
      children [
        Solid {
          translation 0.1 0.03 0
          children [
            Shape {
              appearance DEF ARM_COLOR PBRAppearance {
                baseColor 0.7999999999999999 0 0
                roughness 1
                metalness 0
              }
              geometry DEF ARM_BOX Box {
                size 0.15 0.05 0.1
              }
            }
            HingeJoint {
              jointParameters HingeJointParameters {
                axis 0 0 1
                anchor 0.055 0.00625 0.06
                minStop -1.57
                maxStop 1.57
              }
              endPoint Solid {
                translation 0.055 0.11249999999999999 0.06
                rotation 0 0 1 3.1416
                children [
                  Shape {
                    appearance USE ARM_COLOR
                    geometry DEF ARM_LINK1 Box {
                      size 0.04 0.25 0.02
                    }
                  }
                ]
                name "solid(4)"
                boundingObject USE ARM_LINK1
                physics Physics {
                }
              }
            }
            HingeJoint {
              jointParameters HingeJointParameters {
                axis 0 0 1
                anchor 0.055 0.00625 -0.06
                minStop -1.57
                maxStop 1.57
              }
              endPoint Solid {
                translation 0.055 0.1125 -0.06
                rotation 0 0 1 3.1416
                children [
                  Shape {
                    appearance USE ARM_COLOR
                    geometry USE ARM_LINK1
                  }
                ]
                name "solid(5)"
                boundingObject USE ARM_LINK1
                physics Physics {
                }
              }
            }
          ]
          name "solid(6)"
          boundingObject USE ARM_BOX
          physics Physics {
          }
        }
      ]
    }
  ]
  boundingObject USE BODY
  physics Physics {
  }
}
