#VRML_SIM R2019b utf8
WorldInfo {
}
Viewpoint {
  orientation -0.02991305175904262 -0.9991394366859961 0.02873317582953658 4.751760362412888
  position 1.9880027773829705 0.3226616049884464 0.17430017628369576
}
TexturedBackground {
}
TexturedBackgroundLight {
}
Floor {
}
Robot {
  translation 0 0.05 0
  children [
    DEF BODY Group {
      children [
        Shape {
          appearance DEF BODY_COLOR PBRAppearance {
            baseColor 0.533333 0.541176 0.521569
            roughness 1
            metalness 0
          }
          geometry Box {
            size 0.4 0.01 0.2
          }
        }
        Transform {
          translation 0 0.055 0.09
          rotation 1 0 0 1.57
          children [
            Shape {
              appearance USE BODY_COLOR
              geometry DEF BODY_LAYER Box {
                size 0.4 0.02 0.1
              }
            }
          ]
          rotationStep 0.261799
        }
        Transform {
          translation 0 0.055 -0.09
          rotation 1 0 0 1.57
          children [
            Shape {
              appearance USE BODY_COLOR
              geometry USE BODY_LAYER
            }
          ]
        }
      ]
    }
    DEF WHEELS Group {
      children [
        HingeJoint {
          jointParameters HingeJointParameters {
            axis 0 0 1
            anchor 0.1 0 0.105
          }
          endPoint Solid {
            translation 0.1 0 0.105
            rotation 1 0 0 1.57
            children [
              Shape {
                appearance DEF WHEEL_COLOR PBRAppearance {
                  baseColor 0 0 0
                  roughness 1
                  metalness 0
                }
                geometry DEF WHEEL_GEO Cylinder {
                  height 0.01
                  radius 0.05
                }
              }
            ]
          }
        }
        HingeJoint {
          jointParameters HingeJointParameters {
            axis 0 0 1
            anchor 0.1 0 -0.105
          }
          endPoint Solid {
            translation 0.1 0 -0.105
            rotation 1 0 0 1.57
            children [
              Shape {
                appearance USE WHEEL_COLOR
                geometry USE WHEEL_GEO
              }
            ]
            name "solid(1)"
          }
        }
        HingeJoint {
          jointParameters HingeJointParameters {
            axis 0 0 1
            anchor -0.1 0 0.105
          }
          endPoint Solid {
            translation -0.1 0 0.105
            rotation 1 0 0 1.57
            children [
              Shape {
                appearance USE WHEEL_COLOR
                geometry USE WHEEL_GEO
              }
            ]
            name "solid(2)"
          }
        }
        HingeJoint {
          jointParameters HingeJointParameters {
            axis 0 0 1
            anchor -0.1 0 -0.105
          }
          endPoint Solid {
            translation -0.1 0 -0.105
            rotation 1 0 0 1.57
            children [
              Shape {
                appearance USE WHEEL_COLOR
                geometry USE WHEEL_GEO
              }
            ]
            name "solid(3)"
          }
        }
      ]
    }
    DEF ROBOT_ARM Group {
      children [
        Transform {
          translation 0.1 0.03 0
          children [
            Shape {
              appearance DEF ARM_COLOR PBRAppearance {
                baseColor 0.7999999999999999 0 0
                roughness 1
                metalness 0
              }
              geometry Box {
                size 0.15 0.05 0.1
              }
            }
            HingeJoint {
              jointParameters HingeJointParameters {
                axis 0 0 1
                anchor 0.055 0.00625 0.06
                minStop -1.57
                maxStop 1.57
              }
              endPoint Solid {
                translation 0.055 0.11249999999999999 0.06
                rotation 0 0 1 3.1416
                children [
                  Shape {
                    appearance USE ARM_COLOR
                    geometry DEF ARM_LINK1 Box {
                      size 0.04 0.25 0.02
                    }
                  }
                ]
                name "solid(4)"
              }
            }
            HingeJoint {
              jointParameters HingeJointParameters {
                axis 0 0 1
                anchor 0.055 0.00625 -0.06
                minStop -1.57
                maxStop 1.57
              }
              endPoint Solid {
                translation 0.055 0.1125 -0.06
                rotation 0 0 1 3.1416
                children [
                  Shape {
                    appearance USE ARM_COLOR
                    geometry USE ARM_LINK1
                  }
                ]
                name "solid(5)"
              }
            }
          ]
        }
      ]
    }
  ]
}
