#VRML_SIM R2019b utf8
WorldInfo {
}
Viewpoint {
  orientation 0.4858004021764408 -0.8141164371684336 -0.31813895702567474 4.9477254342353
  position 0.5674501308984254 0.47363386466559654 0.13526644776219915
}
TexturedBackground {
}
TexturedBackgroundLight {
}
Floor {
}
Robot {
  translation 0 0.025 0
  children [
    DEF BODY Group {
      children [
        Shape {
          appearance DEF BODY_COLOR PBRAppearance {
            baseColor 0.533333 0.541176 0.521569
            roughness 1
            metalness 0
          }
          geometry Box {
            size 0.4 0.01 0.2
          }
        }
        Transform {
          translation 0 0.055 0.09
          rotation 1 0 0 1.57
          children [
            Shape {
              appearance DEF BODY_COLOR PBRAppearance {
                baseColor 0.533333 0.541176 0.521569
                roughness 1
                metalness 0
              }
              geometry Box {
                size 0.4 0.02 0.1
              }
            }
          ]
          rotationStep 0.261799
        }
        Transform {
          translation 0 0.055 -0.09
          rotation 1 0 0 1.57
          children [
            Shape {
              appearance DEF BODY_COLOR PBRAppearance {
                baseColor 0.533333 0.541176 0.521569
                roughness 1
                metalness 0
              }
              geometry Box {
                size 0.4 0.02 0.1
              }
            }
          ]
        }
      ]
    }
    DEF WHEELS Group {
      children [
        HingeJoint {
          jointParameters HingeJointParameters {
          }
          endPoint Solid {
            children [
              Shape {
                appearance DEF WHEEL_COLOR PBRAppearance {
                }
                geometry Cylinder {
                  height 0.1
                  radius 0.05
                }
              }
            ]
          }
        }
      ]
    }
    Group {
    }
  ]
}
