#VRML_SIM R2019b utf8
WorldInfo {
}
Viewpoint {
  orientation 0.045195136989657915 -0.9983880192530932 -0.03433311236068229 4.982316084377215
  position 0.9760049526170718 0.1963817690339479 0.2730775828991282
}
TexturedBackground {
}
TexturedBackgroundLight {
}
Floor {
}
Robot {
  translation 0 0.05 0
  children [
    DEF BODY Group {
      children [
        Shape {
          appearance DEF BODY_COLOR PBRAppearance {
            baseColor 0.533333 0.541176 0.521569
            roughness 1
            metalness 0
          }
          geometry Box {
            size 0.4 0.01 0.2
          }
        }
        Transform {
          translation 0 0.055 0.09
          rotation 1 0 0 1.57
          children [
            Shape {
              appearance USE BODY_COLOR
              geometry DEF BODY_LAYER Box {
                size 0.4 0.02 0.1
              }
            }
          ]
          rotationStep 0.261799
        }
        Transform {
          translation 0 0.055 -0.09
          rotation 1 0 0 1.57
          children [
            Shape {
              appearance USE BODY_COLOR
              geometry USE BODY_LAYER
            }
          ]
        }
      ]
    }
    DEF WHEELS Group {
      children [
        HingeJoint {
          jointParameters HingeJointParameters {
            axis 0 0 1
            anchor 0.1 0 0.105
          }
          endPoint Solid {
            translation 0.1 0 0.105
            rotation 1 0 0 1.57
            children [
              Shape {
                appearance DEF WHEEL_COLOR PBRAppearance {
                  baseColor 0 0 0
                  roughness 1
                  metalness 0
                }
                geometry DEF WHEEL_GEO Cylinder {
                  height 0.01
                  radius 0.05
                }
              }
            ]
          }
        }
        HingeJoint {
          jointParameters HingeJointParameters {
            axis 0 0 1
            anchor 0.1 0 -0.105
          }
          endPoint Solid {
            translation 0.1 0 -0.105
            rotation 1 0 0 1.57
            children [
              Shape {
                appearance USE WHEEL_COLOR
                geometry USE WHEEL_GEO
              }
            ]
            name "solid(1)"
          }
        }
        HingeJoint {
          jointParameters HingeJointParameters {
            axis 0 0 1
            anchor -0.1 0 0.105
          }
          endPoint Solid {
            translation -0.1 0 0.105
            rotation 1 0 0 1.57
            children [
              Shape {
                appearance USE WHEEL_COLOR
                geometry USE WHEEL_GEO
              }
            ]
            name "solid(2)"
          }
        }
        HingeJoint {
          jointParameters HingeJointParameters {
            axis 0 0 1
            anchor -0.1 0 -0.105
          }
          endPoint Solid {
            translation -0.1 0 -0.105
            rotation 1 0 0 1.57
            children [
              Shape {
                appearance USE WHEEL_COLOR
                geometry USE WHEEL_GEO
              }
            ]
            name "solid(3)"
          }
        }
      ]
    }
    DEF ROBOT_ARM Group {
      children [
        Transform {
        }
      ]
    }
  ]
}
