#VRML_SIM R2019b utf8
WorldInfo {
}
Viewpoint {
  orientation 0.08890700268486575 0.9402603111681126 0.32864280323116374 3.6397608284883916
  position -0.7690771239730368 0.612371958889024 -0.8395642916341819
}
TexturedBackground {
}
TexturedBackgroundLight {
}
Floor {
}
Robot {
  translation 0 0.05 0
  children [
    DEF BODY Group {
      children [
        Shape {
          appearance DEF BODY_COLOR PBRAppearance {
            baseColor 0.533333 0.541176 0.521569
            roughness 1
            metalness 0
          }
          geometry Box {
            size 0.4 0.01 0.2
          }
        }
        Transform {
          translation 0 0.055 0.09
          rotation 1 0 0 1.57
          children [
            Shape {
              appearance DEF BODY_COLOR PBRAppearance {
                baseColor 0.533333 0.541176 0.521569
                roughness 1
                metalness 0
              }
              geometry Box {
                size 0.4 0.02 0.1
              }
            }
          ]
          rotationStep 0.261799
        }
        Transform {
          translation 0 0.055 -0.09
          rotation 1 0 0 1.57
          children [
            Shape {
              appearance DEF BODY_COLOR PBRAppearance {
                baseColor 0.533333 0.541176 0.521569
                roughness 1
                metalness 0
              }
              geometry Box {
                size 0.4 0.02 0.1
              }
            }
          ]
        }
      ]
    }
    DEF WHEELS Group {
      children [
        HingeJoint {
          jointParameters HingeJointParameters {
          }
          endPoint Solid {
            translation 0.1 0 0.105
            rotation 1 0 0 1.57
            children [
              Shape {
                appearance DEF WHEEL_COLOR PBRAppearance {
                  baseColor 0 0 0
                  roughness 1
                  metalness 0
                }
                geometry Cylinder {
                  height 0.01
                  radius 0.05
                }
              }
            ]
          }
        }
        HingeJoint {
          jointParameters HingeJointParameters {
          }
          endPoint Solid {
            translation 0.1 0 -0.105
            rotation 1 0 0 1.57
            children [
              Shape {
                appearance USE WHEEL_COLOR
                geometry DEF WHEEL_COLOR Cylinder {
                  height 0.01
                  radius 0.05
                }
              }
            ]
            name "solid(1)"
          }
        }
        HingeJoint {
          jointParameters HingeJointParameters {
          }
          endPoint Solid {
            translation -0.1 0 0.105
            rotation 1 0 0 1.57
            children [
              Shape {
                appearance DEF WHEEL_COLOR PBRAppearance {
                  baseColor 0 0 0
                  roughness 1
                  metalness 0
                }
                geometry DEF WHEEL_COLOR Cylinder {
                  height 0.01
                  radius 0.05
                }
              }
            ]
            name "solid(2)"
          }
        }
        HingeJoint {
          jointParameters HingeJointParameters {
          }
          endPoint Solid {
            translation -0.1 0 -0.105
            rotation 1 0 0 1.57
            children [
              Shape {
                appearance DEF WHEEL_COLOR PBRAppearance {
                  baseColor 0 0 0
                  roughness 1
                  metalness 0
                }
                geometry DEF WHEEL_COLOR Cylinder {
                  height 0.01
                  radius 0.05
                }
              }
            ]
            name "solid(3)"
          }
        }
      ]
    }
    Group {
    }
  ]
}
